<?xml version="0.0" ?>
<robot name="gripper">

  <material name="c_joint">
    <color rgba="0.5 0.5 0.5 1"/>
  </material>

  <material name="c_arm">
    <color rgba="0.9 0.9 0.2 1"/>
  </material> 

  <material name="c_pincher">
    <color rgba="0.2 0.2 1.0 1"/>
  </material>   

  <link name="world" />

  <link name="base"/>

  <link name="shoulder">
    <visual>
      <origin xyz="0 0 0" rpy="0 0 0" />
      <geometry>
        <sphere radius="0.1"/>
      </geometry>
      <material name="c_joint"/>
    </visual>
    <inertial>
      <origin xyz="0 0 0" rpy="0 0 0" />
      <mass value="1."/>
      <inertia ixx="1.0" ixy="0.0" ixz="0.0" iyy="1.0" iyz="0.0" izz="1.0"/>
    </inertial>
  </link>

  <link name="upper_arm">
  	<visual>
  	  <origin xyz="0.25 0 0" rpy="0 1.57086 0" />
      <geometry>
        <cylinder length="0.5" radius="0.05"/>
      </geometry>
      <material name="c_arm"/>
    </visual>
    <collision>
      <origin xyz="0.25 0 0" rpy="0 1.57086 0" />
      <geometry>
        <cylinder length="0.5" radius="0.05"/>
      </geometry>
    </collision>
    <inertial>
      <origin xyz="0.25 0 0" rpy="0 0 0" />
      <mass value="1."/>
      <inertia ixx="1.0" ixy="0.0" ixz="0.0" iyy="1.0" iyz="0.0" izz="1.0"/>
    </inertial>
  </link>

  <link name="arm_elbow">
  	<visual>
  		<origin xyz="0 0 0" rpy="0 0 0" />
  		<geometry>
  			<sphere radius="0.07" />
  		</geometry>
  		<material name="c_joint"/>
  	</visual>
  	<inertial>
      <origin xyz="0 0 0" rpy="0 0 0" />
      <mass value="1."/>
      <inertia ixx="1.0" ixy="0.0" ixz="0.0" iyy="1.0" iyz="0.0" izz="1.0"/>
    </inertial>
  </link>

  <link name="lower_arm">
  	<visual>
  	  <origin xyz="0.25 0 0" rpy="0 1.57086 0" />
      <geometry>
        <cylinder length="0.5" radius="0.05"/>
      </geometry>
      <material name="c_arm"/>
    </visual>
    <collision>
      <origin xyz="0.25 0 0" rpy="0 1.57086 0" />
      <geometry>
        <cylinder length="0.5" radius="0.05"/>
      </geometry>
    </collision>
    <inertial>
      <origin xyz="0.25 0 0" rpy="0 1.5708 0" />
      <mass value="1."/>
      <inertia ixx="1.0" ixy="0.0" ixz="0.0" iyy="1.0" iyz="0.0" izz="1.0"/>
    </inertial>
  </link>

  <link name="wrist">
  	<visual>
  	  <origin xyz="0.01 0 0" rpy="0 1.57086 0" />
      <geometry>
        <cylinder length="0.02" radius="0.05"/>
      </geometry>
      <material name="c_joint"/>
    </visual>
    <collision>
      <origin xyz="0.01 0 0" rpy="0 1.57086 0" />
      <geometry>
        <cylinder length="0.02" radius="0.05"/>
      </geometry>
    </collision>
    <inertial>
      <origin xyz="0.01 0 0" rpy="0 1.5708 0" />
      <mass value="1."/>
      <inertia ixx="1.0" ixy="0.0" ixz="0.0" iyy="1.0" iyz="0.0" izz="1.0"/>
    </inertial>
  </link>

  <!-- Pincher -->
  <link name="pincher_bottom_right">
  	<visual>
  	  <origin xyz="0.05 0 0" rpy="0 0 0" />
      <geometry>
        <box size="0.1 0.02 0.04"/>
      </geometry>
      <material name="c_pincher"/>
    </visual>
    <collision>
      <origin xyz="0.05 0 0" rpy="0 0 0" />
      <geometry>
        <box size="0.1 0.02 0.04"/>
      </geometry>
    </collision>
    <inertial>
      <origin xyz="0.05 0 0" rpy="0 0 0" />
      <mass value="0.05"/>
      <inertia ixx="0.1" ixy="0.0" ixz="0.0" iyy="0.1" iyz="0.0" izz="0.1"/>
    </inertial>
    <contact>
      <lateral_friction value="1.0"/>
      <rolling_friction value="0.0"/>
      <contact_cfm value="0.0"/>
      <contact_erp value="1.0"/>
    </contact>
  </link>

  <link name="pincher_bottom_left">
  	<visual>
  	  <origin xyz="0.05 0 0" rpy="0 0 0" />
      <geometry>
        <box size="0.1 0.02 0.04"/>
      </geometry>
      <material name="c_pincher"/>
    </visual>
    <collision>
      <origin xyz="0.05 0 0" rpy="0 0 0" />
      <geometry>
        <box size="0.1 0.02 0.04"/>
      </geometry>
    </collision>
    <inertial>
      <origin xyz="0.05 0 0" rpy="0 0 0" />
      <mass value="0.05"/>
      <inertia ixx="0.1" ixy="0.0" ixz="0.0" iyy="0.1" iyz="0.0" izz="0.1"/>
    </inertial>
    <contact>
      <lateral_friction value="1.0"/>
      <rolling_friction value="0.0"/>
      <contact_cfm value="0.0"/>
      <contact_erp value="1.0"/>
    </contact>
  </link>

  <link name="pincher_top_right">
    <contact>
      <lateral_friction value="1.0"/>
      <inertia_scaling value="3.0"/>
    </contact>
  	<visual>
  	  <origin xyz="0.05 0 0" rpy="0 0 0" />
      <geometry>
        <box size="0.1 0.02 0.04"/>
      </geometry>
      <material name="c_pincher"/>
    </visual>
    <collision>
      <origin xyz="0.05 0 0" rpy="0 0 0" />
      <geometry>
        <box size="0.1 0.02 0.04"/>
      </geometry>
    </collision>
    <inertial>
      <origin xyz="0.05 0 0" rpy="0 0 0" />
      <mass value="0.05"/>
      <inertia ixx="0.1" ixy="0.0" ixz="0.0" iyy="0.1" iyz="0.0" izz="0.1"/>
    </inertial>
    <contact>
      <lateral_friction value="1.0"/>
      <rolling_friction value="0.0"/>
      <contact_cfm value="0.0"/>
      <contact_erp value="1.0"/>
    </contact>
  </link>

  <link name="pincher_top_left">
    <contact>
      <lateral_friction value="1.0"/>
      <inertia_scaling value="3.0"/>
    </contact>
  	<visual>
  	  <origin xyz="0.05 0 0" rpy="0 0 0" />
      <geometry>
        <box size="0.1 0.02 0.04"/>
      </geometry>
      <material name="c_pincher"/>
    </visual>
    <collision>
      <origin xyz="0.05 0 0" rpy="0 0 0" />
      <geometry>
        <box size="0.1 0.02 0.04"/>
      </geometry>
    </collision>
    <inertial>
      <origin xyz="0.05 0 0" rpy="0 0 0" />
      <mass value="0.05"/>
      <inertia ixx="0.1" ixy="0.0" ixz="0.0" iyy="0.1" iyz="0.0" izz="0.1"/>
    </inertial>
    <contact>
      <lateral_friction value="1.0"/>
      <rolling_friction value="0.0"/>
      <contact_cfm value="0.0"/>
      <contact_erp value="1.0"/>
    </contact>
  </link>

  <!-- Joints -->
  <joint name="world_joint"  type="fixed">
    <origin xyz="0 0 0" rpy="0 0 0" />
    <parent link="world"/>
    <child link="base"/>
  </joint>

  <joint name="joint_shoulder_z" type="revolute">
  	<parent link="base" />
  	<child link="shoulder" />
  	<origin xyz="0 0 0" rpy="0 0 0" />
  	<axis xyz="0 0 1" />
    <limit effort="10.0" lower="-1.57" upper="1.57" velocity="1"/>
  </joint>

  <joint name="joint_shoulder_y" type="revolute">
    <parent link="shoulder" />
    <child link="upper_arm" />
    <origin xyz="0 0 0" rpy="0 0 0" />
    <axis xyz="0 1 0" />
    <limit effort="10.0" lower="-1.57" upper="1.57" velocity="1"/>
  </joint>

  <joint name="joint_upper_z" type="revolute">
  	<parent link="upper_arm" />
  	<child link="arm_elbow" />
  	<origin xyz="0.5 0 0" rpy="0 0 0" />
  	<axis xyz="0 0 1" />
    <limit effort="10.0" lower="-2.36" upper="2.36" velocity="1"/>
  </joint>

  <joint name="joint_upper_y" type="revolute">
  	<parent link="arm_elbow" />
  	<child link="lower_arm" />
  	<origin xyz="0 0 0" rpy="0 0 0" />
  	<axis xyz="0 1 0" />
    <limit effort="10.0" lower="-2.36" upper="2.36" velocity="1"/>
  </joint>

  <joint name="joint_wrist_x" type="revolute">
  	<parent link="lower_arm" />
  	<child link="wrist" />
  	<origin xyz="0.5 0 0" rpy="0 0 0" />
  	<axis xyz="1 0 0" />
    <limit effort="0.01" lower="-3.14" upper="3.14" velocity="0.01"/>
  </joint>

  <joint name="joint_pincher_bottom_right" type="revolute">
  	<parent link="wrist" />
  	<child link="pincher_bottom_right" />
  	<origin xyz="0.01 -0.035 0" rpy="0 0 -0.7854" />
  	<axis xyz="0 0 1" />
    <limit effort="10.0" lower="-0.7854" upper="0.53" velocity="1"/>
  </joint>

  <joint name="joint_pincher_bottom_left" type="revolute">
  	<parent link="wrist" />
  	<child link="pincher_bottom_left" />
  	<origin xyz="0.01 0.035 0" rpy="0 0 0.7854" />
  	<axis xyz="0 0 1" />
  	<limit effort="10.0" lower="-0.53" upper="0.7854" velocity="1"/>
  </joint>

  <joint name="joint_pincher_top_right" type="fixed">
  	<parent link="pincher_bottom_right" />
  	<child link="pincher_top_right" />
  	<origin xyz="0.1 0 0" rpy="0 0 0.7854" />
  	<axis xyz="0 0 1" />
  </joint>

  <joint name="joint_pincher_top_left" type="fixed">
  	<parent link="pincher_bottom_left" />
  	<child link="pincher_top_left" />
  	<origin xyz="0.1 0 0" rpy="0 0 -0.7854" />
  	<axis xyz="0 0 1" />
  </joint>

</robot>
